Workbook

Sheet Cover
B2: MediFind — Test Requirements Workbook
B3: Emergency Response Ecosystem · Patient · Caregiver · Responder · Admin
B4: Project: MediFind FYP | Date: 2026-09-17 | Version: 2.2 (results recorded; privacy, chat lock and calls added; v1.0 dated 2026-05-30)
B6: STATUS LEGEND
B7: PASS | C7: Test passed — behaviour matches expected result
B8: FAIL | C8: Test failed — defect raised
B9: PENDING | C9: Not yet executed
B10: N/A | C10: Not applicable for this configuration
B11: BLOCKED | C11: Cannot be tested — dependency unresolved
B13: HOW TO USE
B14: 1. | C14: Edit only the Status (dropdown) and Notes / Defect Ref columns in each test sheet.
B15: 2. | C15: SRS Ref links every test to a functional requirement in MediFind_Requirements_Analysis.docx; "Beyond SRS" marks extra features.
B16: 3. | C16: SUMMARY and SRS_TRACEABILITY recalculate automatically from the Status and SRS Ref columns.
B17: 4. | C17: CHANGE_LOG lists what changed from version 1.0 and why.
B19: SHEETS IN THIS WORKBOOK
B20: AUTH | C20: Registration, Login, Lockout, Password Reset, Token Refresh, Logout
B21: PATIENT_SOS | C21: Hold-to-SOS, 60-second Countdown, Categories, Tracking, ETA, Cancellation
B22: SECURITY_SOS | C22: False SOS Prevention, Abuse Limits, Security Controls
B23: RESPONDER | C23: Alerts, Accept/Reject, Availability, Navigation, Status, Resolve
B24: CAREGIVER | C24: Linking, Live Map, Notifications, History
B25: MEDICAL | C25: Medical Profile, Reports, Emergency Contacts, Data Isolation
B26: CHAT | C26: Real-time Chat, Privacy, History, Quick Phrases (Deaf), Media
B27: PRIVACY_CALLS | C27: Contact Privacy, Emergency Chat Lock, Phone Calls, In-app Voice/Video Calls, Performance, AI & Layout
B28: PROFILE | C28: View/Edit Profile, Avatar Upload, Account Deletion (beyond SRS)
B29: ACCESSIBILITY | C29: Deaf Mode, High Contrast, Font Scaling, Voice Guidance, Vibration
B30: NOTIFICATIONS | C30: Self-hosted Push, In-App, Broadcast, Admin Web Portal
B31: NAVIGATION_UI | C31: Sidebar, Stateful Routing, Quick Actions, Performance
... B36: CHANGE_LOG | C36: Changes from version 1.0

Sheet SUMMARY
A1: MediFind — Test Requirements Summary
A3: # | B3: Test Area | C3: Total | D3: PASS | E3: FAIL | F3: PENDING | G3: BLOCKED | H3: N/A | I3: Pass Rate
A4: 1 | B4: AUTH | C4: =COUNTA(AUTH!$A$4:$A$23)-COUNTIF(AUTH!$A$4:$A$23," *") | D4: =COUNTIF(AUTH!$H$4:$H$23,"PASS") | E4: =COUNTIF(AUTH!$H$4:$H$23,"FAIL") | F4: =COUNTIF(AUTH!$H$4:$H$23,"PENDING") | G4: =COUNTIF(AUTH!$H$4:$H$23,"BLOCKED") | H4: =COUNTIF(AUTH!$H$4:$H$23,"N/A") | I4: =IF(C4-H4=0,0,D4/(C4-H4))
A5: 2 | B5: PATIENT_SOS | C5: =COUNTA(PATIENT_SOS!$A$4:$A$21)-COUNTIF(PATIENT_SOS!$A$4:$A$21," *") | D5: =COUNTIF(PATIENT_SOS!$H$4:$H$21,"PASS") | E5: =COUNTIF(PATIENT_SOS!$H$4:$H$21,"FAIL") | F5: =COUNTIF(PATIENT_SOS!$H$4:$H$21,"PENDING") | G5: =COUNTIF(PATIENT_SOS!$H$4:$H$21,"BLOCKED") | H5: =COUNTIF(PATIENT_SOS!$H$4:$H$21,"N/A") | I5: =IF(C5-H5=0,0,D5/(C5-H5))
A6: 3 | B6: SECURITY_SOS | C6: =COUNTA(SECURITY_SOS!$A$4:$A$18)-COUNTIF(SECURITY_SOS!$A$4:$A$18," *") | D6: =COUNTIF(SECURITY_SOS!$H$4:$H$18,"PASS") | E6: =COUNTIF(SECURITY_SOS!$H$4:$H$18,"FAIL") | F6: =COUNTIF(SECURITY_SOS!$H$4:$H$18,"PENDING") | G6: =COUNTIF(SECURITY_SOS!$H$4:$H$18,"BLOCKED") | H6: =COUNTIF(SECURITY_SOS!$H$4:$H$18,"N/A") | I6: =IF(C6-H6=0,0,D6/(C6-H6))
A7: 4 | B7: RESPONDER | C7: =COUNTA(RESPONDER!$A$4:$A$21)-COUNTIF(RESPONDER!$A$4:$A$21," *") | D7: =COUNTIF(RESPONDER!$H$4:$H$21,"PASS") | E7: =COUNTIF(RESPONDER!$H$4:$H$21,"FAIL") | F7: =COUNTIF(RESPONDER!$H$4:$H$21,"PENDING") | G7: =COUNTIF(RESPONDER!$H$4:$H$21,"BLOCKED") | H7: =COUNTIF(RESPONDER!$H$4:$H$21,"N/A") | I7: =IF(C7-H7=0,0,D7/(C7-H7))
A8: 5 | B8: CAREGIVER | C8: =COUNTA(CAREGIVER!$A$4:$A$15)-COUNTIF(CAREGIVER!$A$4:$A$15," *") | D8: =COUNTIF(CAREGIVER!$H$4:$H$15,"PASS") | E8: =COUNTIF(CAREGIVER!$H$4:$H$15,"FAIL") | F8: =COUNTIF(CAREGIVER!$H$4:$H$15,"PENDING") | G8: =COUNTIF(CAREGIVER!$H$4:$H$15,"BLOCKED") | H8: =COUNTIF(CAREGIVER!$H$4:$H$15,"N/A") | I8: =IF(C8-H8=0,0,D8/(C8-H8))
A9: 6 | B9: MEDICAL | C9: =COUNTA(MEDICAL!$A$4:$A$14)-COUNTIF(MEDICAL!$A$4:$A$14," *") | D9: =COUNTIF(MEDICAL!$H$4:$H$14,"PASS") | E9: =COUNTIF(MEDICAL!$H$4:$H$14,"FAIL") | F9: =COUNTIF(MEDICAL!$H$4:$H$14,"PENDING") | G9: =COUNTIF(MEDICAL!$H$4:$H$14,"BLOCKED") | H9: =COUNTIF(MEDICAL!$H$4:$H$14,"N/A") | I9: =IF(C9-H9=0,0,D9/(C9-H9))
A10: 7 | B10: CHAT | C10: =COUNTA(CHAT!$A$4:$A$17)-COUNTIF(CHAT!$A$4:$A$17," *") | D10: =COUNTIF(CHAT!$H$4:$H$17,"PASS") | E10: =COUNTIF(CHAT!$H$4:$H$17,"FAIL") | F10: =COUNTIF(CHAT!$H$4:$H$17,"PENDING") | G10: =COUNTIF(CHAT!$H$4:$H$17,"BLOCKED") | H10: =COUNTIF(CHAT!$H$4:$H$17,"N/A") | I10: =IF(C10-H10=0,0,D10/(C10-H10))
A11: 8 | B11: PRIVACY_CALLS | C11: =COUNTA(PRIVACY_CALLS!$A$4:$A$40)-COUNTIF(PRIVACY_CALLS!$A$4:$A$40," *") | D11: =COUNTIF(PRIVACY_CALLS!$H$4:$H$40,"PASS") | E11: =COUNTIF(PRIVACY_CALLS!$H$4:$H$40,"FAIL") | F11: =COUNTIF(PRIVACY_CALLS!$H$4:$H$40,"PENDING") | G11: =COUNTIF(PRIVACY_CALLS!$H$4:$H$40,"BLOCKED") | H11: =COUNTIF(PRIVACY_CALLS!$H$4:$H$40,"N/A") | I11: =IF(C11-H11=0,0,D11/(C11-H11))
A12: 9 | B12: PROFILE | C12: =COUNTA(PROFILE!$A$4:$A$9)-COUNTIF(PROFILE!$A$4:$A$9," *") | D12: =COUNTIF(PROFILE!$H$4:$H$9,"PASS") | E12: =COUNTIF(PROFILE!$H$4:$H$9,"FAIL") | F12: =COUNTIF(PROFILE!$H$4:$H$9,"PENDING") | G12: =COUNTIF(PROFILE!$H$4:$H$9,"BLOCKED") | H12: =COUNTIF(PROFILE!$H$4:$H$9,"N/A") | I12: =IF(C12-H12=0,0,D12/(C12-H12))
A13: 10 | B13: ACCESSIBILITY | C13: =COUNTA(ACCESSIBILITY!$A$4:$A$22)-COUNTIF(ACCESSIBILITY!$A$4:$A$22," *") | D13: =COUNTIF(ACCESSIBILITY!$H$4:$H$22,"PASS") | E13: =COUNTIF(ACCESSIBILITY!$H$4:$H$22,"FAIL") | F13: =COUNTIF(ACCESSIBILITY!$H$4:$H$22,"PENDING") | G13: =COUNTIF(ACCESSIBILITY!$H$4:$H$22,"BLOCKED") | H13: =COUNTIF(ACCESSIBILITY!$H$4:$H$22,"N/A") | I13: =IF(C13-H13=0,0,D13/(C13-H13))
A14: 11 | B14: NOTIFICATIONS | C14: =COUNTA(NOTIFICATIONS!$A$4:$A$19)-COUNTIF(NOTIFICATIONS!$A$4:$A$19," *") | D14: =COUNTIF(NOTIFICATIONS!$H$4:$H$19,"PASS") | E14: =COUNTIF(NOTIFICATIONS!$H$4:$H$19,"FAIL") | F14: =COUNTIF(NOTIFICATIONS!$H$4:$H$19,"PENDING") | G14: =COUNTIF(NOTIFICATIONS!$H$4:$H$19,"BLOCKED") | H14: =COUNTIF(NOTIFICATIONS!$H$4:$H$19,"N/A") | I14: =IF(C14-H14=0,0,D14/(C14-H14))
A15: 12 | B15: NAVIGATION_UI | C15: =COUNTA(NAVIGATION_UI!$A$4:$A$8)-COUNTIF(NAVIGATION_UI!$A$4:$A$8," *") | D15: =COUNTIF(NAVIGATION_UI!$H$4:$H$8,"PASS") | E15: =COUNTIF(NAVIGATION_UI!$H$4:$H$8,"FAIL") | F15: =COUNTIF(NAVIGATION_UI!$H$4:$H$8,"PENDING") | G15: =COUNTIF(NAVIGATION_UI!$H$4:$H$8,"BLOCKED") | H15: =COUNTIF(NAVIGATION_UI!$H$4:$H$8,"N/A") | I15: =IF(C15-H15=0,0,D15/(C15-H15))
A16: 13 | B16: ADMIN_PORTAL | C16: =COUNTA(ADMIN_PORTAL!$A$4:$A$19)-COUNTIF(ADMIN_PORTAL!$A$4:$A$19," *") | D16: =COUNTIF(ADMIN_PORTAL!$H$4:$H$19,"PASS") | E16: =COUNTIF(ADMIN_PORTAL!$H$4:$H$19,"FAIL") | F16: =COUNTIF(ADMIN_PORTAL!$H$4:$H$19,"PENDING") | G16: =COUNTIF(ADMIN_PORTAL!$H$4:$H$19,"BLOCKED") | H16: =COUNTIF(ADMIN_PORTAL!$H$4:$H$19,"N/A") | I16: =IF(C16-H16=0,0,D16/(C16-H16))
A17: 14 | B17: BACKEND_API | C17: =COUNTA(BACKEND_API!$A$4:$A$23)-COUNTIF(BACKEND_API!$A$4:$A$23," *") | D17: =COUNTIF(BACKEND_API!$H$4:$H$23,"PASS") | E17: =COUNTIF(BACKEND_API!$H$4:$H$23,"FAIL") | F17: =COUNTIF(BACKEND_API!$H$4:$H$23,"PENDING") | G17: =COUNTIF(BACKEND_API!$H$4:$H$23,"BLOCKED") | H17: =COUNTIF(BACKEND_API!$H$4:$H$23,"N/A") | I17: =IF(C17-H17=0,0,D17/(C17-H17))
B18: TOTAL | C18: =SUM(C4:C17) | D18: =SUM(D4:D17) | E18: =SUM(E4:E17) | F18: =SUM(F4:F17) | G18: =SUM(G4:G17) | H18: =SUM(H4:H17) | I18: =IF(C18-H18=0,0,D18/(C18-H18))
B20: Totals count test rows (section headers excluded). Pass Rate = PASS ÷ (Total − N/A).

Sheet SRS_TRACEABILITY
A1: MediFind — SRS Functional Requirement Traceability
A2: FR ID | B2: Module | C2: Requirement (SRS) | D2: Test Cases | E2: Coverage | F2: Test Case IDs
A3: FR1.1 | B3: Authentication | C3: Register via email, full name, phone number, and role selection | D3: =COUNTIF(AUTH!$B$4:$B$23,"*FR1.1*")+COUNTIF(PATIENT_SOS!$B$4:$B$21,"*FR1.1*")+COUNTIF(SECURITY_SOS!$B$4:$B$18,"*FR1.1*")+COUNTIF(RESPONDER!$B$4:$B$21,"*FR1.1*")+COUNTIF(CAREGIVER!$B$4:$B$15,"*FR1.1*")+COUNTIF(MEDICAL!$B$4:$B$14,"*FR1.1*")+COUNTIF(CHAT!$B$4:$B$17,"*FR1.1*")+COUNTIF(PRIVACY_CALLS!$B$4:$B$40,"*FR1.1*")+COUNTIF(PROFILE!$B$4:$B$9,"*FR1.1*")+COUNTIF(ACCESSIBILITY!$B$4:$B$22,"*FR1.1*")+COUNTIF(NOTIFICATIONS!$B$4:$B$19,"*FR1.1*")+COUNTIF(NAVIGATION_UI!$B$4:$B$8,"*FR1.1*")+COUNTIF(ADMIN_PORTAL!$B$4:$B$19,"*FR1.1*")+COUNTIF(BACKEND_API!$B$4:$B$23,"*FR1.1*") | E3: =IF(D3>=2,"Covered",IF(D3=1,"Minimal","GAP")) | F3: AUTH-01, AUTH-02, AUTH-03, AUTH-04, AUTH-05, AUTH-06, API-01
A4: FR1.2 | B4: Authentication | C4: Secure login with email/password + JWT (24h access / 30d refresh) | D4: =COUNTIF(AUTH!$B$4:$B$23,"*FR1.2*")+COUNTIF(PATIENT_SOS!$B$4:$B$21,"*FR1.2*")+COUNTIF(SECURITY_SOS!$B$4:$B$18,"*FR1.2*")+COUNTIF(RESPONDER!$B$4:$B$21,"*FR1.2*")+COUNTIF(CAREGIVER!$B$4:$B$15,"*FR1.2*")+COUNTIF(MEDICAL!$B$4:$B$14,"*FR1.2*")+COUNTIF(CHAT!$B$4:$B$17,"*FR1.2*")+COUNTIF(PRIVACY_CALLS!$B$4:$B$40,"*FR1.2*")+COUNTIF(PROFILE!$B$4:$B$9,"*FR1.2*")+COUNTIF(ACCESSIBILITY!$B$4:$B$22,"*FR1.2*")+COUNTIF(NOTIFICATIONS!$B$4:$B$19,"*FR1.2*")+COUNTIF(NAVIGATION_UI!$B$4:$B$8,"*FR1.2*")+COUNTIF(ADMIN_PORTAL!$B$4:$B$19,"*FR1.2*")+COUNTIF(BACKEND_API!$B$4:$B$23,"*FR1.2*") | E4: =IF(D4>=2,"Covered",IF(D4=1,"Minimal","GAP")) | F4: AUTH-07, AUTH-08, AUTH-09, AUTH-10, AUTH-11, AUTH-13, API-02, API-03
A5: FR1.3 | B5: Authentication | C5: Three mobile roles: Patient, Caregiver, Emergency Responder | D5: =COUNTIF(AUTH!$B$4:$B$23,"*FR1.3*")+COUNTIF(PATIENT_SOS!$B$4:$B$21,"*FR1.3*")+COUNTIF(SECURITY_SOS!$B$4:$B$18,"*FR1.3*")+COUNTIF(RESPONDER!$B$4:$B$21,"*FR1.3*")+COUNTIF(CAREGIVER!$B$4:$B$15,"*FR1.3*")+COUNTIF(MEDICAL!$B$4:$B$14,"*FR1.3*")+COUNTIF(CHAT!$B$4:$B$17,"*FR1.3*")+COUNTIF(PRIVACY_CALLS!$B$4:$B$40,"*FR1.3*")+COUNTIF(PROFILE!$B$4:$B$9,"*FR1.3*")+COUNTIF(ACCESSIBILITY!$B$4:$B$22,"*FR1.3*")+COUNTIF(NOTIFICATIONS!$B$4:$B$19,"*FR1.3*")+COUNTIF(NAVIGATION_UI!$B$4:$B$8,"*FR1.3*")+COUNTIF(ADMIN_PORTAL!$B$4:$B$19,"*FR1.3*")+COUNTIF(BACKEND_API!$B$4:$B$23,"*FR1.3*") | E5: =IF(D5>=2,"Covered",IF(D5=1,"Minimal","GAP")) | F5: AUTH-01, AUTH-04
A6: FR1.4 | B6: Authentication | C6: Administrator role via secure web dashboard | D6: =COUNTIF(AUTH!$B$4:$B$23,"*FR1.4*")+COUNTIF(PATIENT_SOS!$B$4:$B$21,"*FR1.4*")+COUNTIF(SECURITY_SOS!$B$4:$B$18,"*FR1.4*")+COUNTIF(RESPONDER!$B$4:$B$21,"*FR1.4*")+COUNTIF(CAREGIVER!$B$4:$B$15,"*FR1.4*")+COUNTIF(MEDICAL!$B$4:$B$14,"*FR1.4*")+COUNTIF(CHAT!$B$4:$B$17,"*FR1.4*")+COUNTIF(PRIVACY_CALLS!$B$4:$B$40,"*FR1.4*")+COUNTIF(PROFILE!$B$4:$B$9,"*FR1.4*")+COUNTIF(ACCESSIBILITY!$B$4:$B$22,"*FR1.4*")+COUNTIF(NOTIFICATIONS!$B$4:$B$19,"*FR1.4*")+COUNTIF(NAVIGATION_UI!$B$4:$B$8,"*FR1.4*")+COUNTIF(ADMIN_PORTAL!$B$4:$B$19,"*FR1.4*")+COUNTIF(BACKEND_API!$B$4:$B$23,"*FR1.4*") | E6: =IF(D6>=2,"Covered",IF(D6=1,"Minimal","GAP")) | F6: AUTH-16
A7: FR1.5 | B7: Authentication | C7: Password reset via email verification + OTP | D7: =COUNTIF(AUTH!$B$4:$B$23,"*FR1.5*")+COUNTIF(PATIENT_SOS!$B$4:$B$21,"*FR1.5*")+COUNTIF(SECURITY_SOS!$B$4:$B$18,"*FR1.5*")+COUNTIF(RESPONDER!$B$4:$B$21,"*FR1.5*")+COUNTIF(CAREGIVER!$B$4:$B$15,"*FR1.5*")+COUNTIF(MEDICAL!$B$4:$B$14,"*FR1.5*")+COUNTIF(CHAT!$B$4:$B$17,"*FR1.5*")+COUNTIF(PRIVACY_CALLS!$B$4:$B$40,"*FR1.5*")+COUNTIF(PROFILE!$B$4:$B$9,"*FR1.5*")+COUNTIF(ACCESSIBILITY!$B$4:$B$22,"*FR1.5*")+COUNTIF(NOTIFICATIONS!$B$4:$B$19,"*FR1.5*")+COUNTIF(NAVIGATION_UI!$B$4:$B$8,"*FR1.5*")+COUNTIF(ADMIN_PORTAL!$B$4:$B$19,"*FR1.5*")+COUNTIF(BACKEND_API!$B$4:$B$23,"*FR1.5*") | E7: =IF(D7>=2,"Covered",IF(D7=1,"Minimal","GAP")) | F7: AUTH-14, AUTH-15
A8: FR1.6 | B8: Authentication | C8: Role-Based Access Control (RBAC) | D8: =COUNTIF(AUTH!$B$4:$B$23,"*FR1.6*")+COUNTIF(PATIENT_SOS!$B$4:$B$21,"*FR1.6*")+COUNTIF(SECURITY_SOS!$B$4:$B$18,"*FR1.6*")+COUNTIF(RESPONDER!$B$4:$B$21,"*FR1.6*")+COUNTIF(CAREGIVER!$B$4:$B$15,"*FR1.6*")+COUNTIF(MEDICAL!$B$4:$B$14,"*FR1.6*")+COUNTIF(CHAT!$B$4:$B$17,"*FR1.6*")+COUNTIF(PRIVACY_CALLS!$B$4:$B$40,"*FR1.6*")+COUNTIF(PROFILE!$B$4:$B$9,"*FR1.6*")+COUNTIF(ACCESSIBILITY!$B$4:$B$22,"*FR1.6*")+COUNTIF(NOTIFICATIONS!$B$4:$B$19,"*FR1.6*")+COUNTIF(NAVIGATION_UI!$B$4:$B$8,"*FR1.6*")+COUNTIF(ADMIN_PORTAL!$B$4:$B$19,"*FR1.6*")+COUNTIF(BACKEND_API!$B$4:$B$23,"*FR1.6*") | E8: =IF(D8>=2,"Covered",IF(D8=1,"Minimal","GAP")) | F8: AUTH-07, AUTH-16, SEC-10, SEC-11, CG-04, API-10, API-11
A9: FR2.1 | B9: Medical Profile | C9: Patients create and maintain a digital medical profile | D9: =COUNTIF(AUTH!$B$4:$B$23,"*FR2.1*")+COUNTIF(PATIENT_SOS!$B$4:$B$21,"*FR2.1*")+COUNTIF(SECURITY_SOS!$B$4:$B$18,"*FR2.1*")+COUNTIF(RESPONDER!$B$4:$B$21,"*FR2.1*")+COUNTIF(CAREGIVER!$B$4:$B$15,"*FR2.1*")+COUNTIF(MEDICAL!$B$4:$B$14,"*FR2.1*")+COUNTIF(CHAT!$B$4:$B$17,"*FR2.1*")+COUNTIF(PRIVACY_CALLS!$B$4:$B$40,"*FR2.1*")+COUNTIF(PROFILE!$B$4:$B$9,"*FR2.1*")+COUNTIF(ACCESSIBILITY!$B$4:$B$22,"*FR2.1*")+COUNTIF(NOTIFICATIONS!$B$4:$B$19,"*FR2.1*")+COUNTIF(NAVIGATION_UI!$B$4:$B$8,"*FR2.1*")+COUNTIF(ADMIN_PORTAL!$B$4:$B$19,"*FR2.1*")+COUNTIF(BACKEND_API!$B$4:$B$23,"*FR2.1*") | E9: =IF(D9>=2,"Covered",IF(D9=1,"Minimal","GAP")) | F9: MED-01, MED-02, MED-03
A10: FR2.2 | B10: Medical Profile | C10: Profile: Blood Type, Allergies, Chronic Diseases, Medications, Disability Type (DEAF/NORMAL) | D10: =COUNTIF(AUTH!$B$4:$B$23,"*FR2.2*")+COUNTIF(PATIENT_SOS!$B$4:$B$21,"*FR2.2*")+COUNTIF(SECURITY_SOS!$B$4:$B$18,"*FR2.2*")+COUNTIF(RESPONDER!$B$4:$B$21,"*FR2.2*")+COUNTIF(CAREGIVER!$B$4:$B$15,"*FR2.2*")+COUNTIF(MEDICAL!$B$4:$B$14,"*FR2.2*")+COUNTIF(CHAT!$B$4:$B$17,"*FR2.2*")+COUNTIF(PRIVACY_CALLS!$B$4:$B$40,"*FR2.2*")+COUNTIF(PROFILE!$B$4:$B$9,"*FR2.2*")+COUNTIF(ACCESSIBILITY!$B$4:$B$22,"*FR2.2*")+COUNTIF(NOTIFICATIONS!$B$4:$B$19,"*FR2.2*")+COUNTIF(NAVIGATION_UI!$B$4:$B$8,"*FR2.2*")+COUNTIF(ADMIN_PORTAL!$B$4:$B$19,"*FR2.2*")+COUNTIF(BACKEND_API!$B$4:$B$23,"*FR2.2*") | E10: =IF(D10>=2,"Covered",IF(D10=1,"Minimal","GAP")) | F10: MED-01, MED-04
A11: FR2.3 | B11: Medical Profile | C11: Medical Report Upload — camera or gallery (image/PDF) | D11: =COUNTIF(AUTH!$B$4:$B$23,"*FR2.3*")+COUNTIF(PATIENT_SOS!$B$4:$B$21,"*FR2.3*")+COUNTIF(SECURITY_SOS!$B$4:$B$18,"*FR2.3*")+COUNTIF(RESPONDER!$B$4:$B$21,"*FR2.3*")+COUNTIF(CAREGIVER!$B$4:$B$15,"*FR2.3*")+COUNTIF(MEDICAL!$B$4:$B$14,"*FR2.3*")+COUNTIF(CHAT!$B$4:$B$17,"*FR2.3*")+COUNTIF(PRIVACY_CALLS!$B$4:$B$40,"*FR2.3*")+COUNTIF(PROFILE!$B$4:$B$9,"*FR2.3*")+COUNTIF(ACCESSIBILITY!$B$4:$B$22,"*FR2.3*")+COUNTIF(NOTIFICATIONS!$B$4:$B$19,"*FR2.3*")+COUNTIF(NAVIGATION_UI!$B$4:$B$8,"*FR2.3*")+COUNTIF(ADMIN_PORTAL!$B$4:$B$19,"*FR2.3*")+COUNTIF(BACKEND_API!$B$4:$B$23,"*FR2.3*") | E11: =IF(D11>=2,"Covered",IF(D11=1,"Minimal","GAP")) | F11: MED-05, MED-06, API-12
A12: FR2.4 | B12: Medical Profile | C12: View, rename, and delete reports | D12: =COUNTIF(AUTH!$B$4:$B$23,"*FR2.4*")+COUNTIF(PATIENT_SOS!$B$4:$B$21,"*FR2.4*")+COUNTIF(SECURITY_SOS!$B$4:$B$18,"*FR2.4*")+COUNTIF(RESPONDER!$B$4:$B$21,"*FR2.4*")+COUNTIF(CAREGIVER!$B$4:$B$15,"*FR2.4*")+COUNTIF(MEDICAL!$B$4:$B$14,"*FR2.4*")+COUNTIF(CHAT!$B$4:$B$17,"*FR2.4*")+COUNTIF(PRIVACY_CALLS!$B$4:$B$40,"*FR2.4*")+COUNTIF(PROFILE!$B$4:$B$9,"*FR2.4*")+COUNTIF(ACCESSIBILITY!$B$4:$B$22,"*FR2.4*")+COUNTIF(NOTIFICATIONS!$B$4:$B$19,"*FR2.4*")+COUNTIF(NAVIGATION_UI!$B$4:$B$8,"*FR2.4*")+COUNTIF(ADMIN_PORTAL!$B$4:$B$19,"*FR2.4*")+COUNTIF(BACKEND_API!$B$4:$B$23,"*FR2.4*") | E12: =IF(D12>=2,"Covered",IF(D12=1,"Minimal","GAP")) | F12: MED-07
A13: FR2.5 | B13: Medical Profile | C13: Medical summary auto-transmitted to responder during active SOS | D13: =COUNTIF(AUTH!$B$4:$B$23,"*FR2.5*")+COUNTIF(PATIENT_SOS!$B$4:$B$21,"*FR2.5*")+COUNTIF(SECURITY_SOS!$B$4:$B$18,"*FR2.5*")+COUNTIF(RESPONDER!$B$4:$B$21,"*FR2.5*")+COUNTIF(CAREGIVER!$B$4:$B$15,"*FR2.5*")+COUNTIF(MEDICAL!$B$4:$B$14,"*FR2.5*")+COUNTIF(CHAT!$B$4:$B$17,"*FR2.5*")+COUNTIF(PRIVACY_CALLS!$B$4:$B$40,"*FR2.5*")+COUNTIF(PROFILE!$B$4:$B$9,"*FR2.5*")+COUNTIF(ACCESSIBILITY!$B$4:$B$22,"*FR2.5*")+COUNTIF(NOTIFICATIONS!$B$4:$B$19,"*FR2.5*")+COUNTIF(NAVIGATION_UI!$B$4:$B$8,"*FR2.5*")+COUNTIF(ADMIN_PORTAL!$B$4:$B$19,"*FR2.5*")+COUNTIF(BACKEND_API!$B$4:$B$23,"*FR2.5*") | E13: =IF(D13>=2,"Covered",IF(D13=1,"Minimal","GAP")) | F13: RSP-02, MED-08
A14: FR2.6 | B14: Medical Profile | C14: HIPAA-compliant data isolation — reports only visible to patient + active responder | D14: =COUNTIF(AUTH!$B$4:$B$23,"*FR2.6*")+COUNTIF(PATIENT_SOS!$B$4:$B$21,"*FR2.6*")+COUNTIF(SECURITY_SOS!$B$4:$B$18,"*FR2.6*")+COUNTIF(RESPONDER!$B$4:$B$21,"*FR2.6*")+COUNTIF(CAREGIVER!$B$4:$B$15,"*FR2.6*")+COUNTIF(MEDICAL!$B$4:$B$14,"*FR2.6*")+COUNTIF(CHAT!$B$4:$B$17,"*FR2.6*")+COUNTIF(PRIVACY_CALLS!$B$4:$B$40,"*FR2.6*")+COUNTIF(PROFILE!$B$4:$B$9,"*FR2.6*")+COUNTIF(ACCESSIBILITY!$B$4:$B$22,"*FR2.6*")+COUNTIF(NOTIFICATIONS!$B$4:$B$19,"*FR2.6*")+COUNTIF(NAVIGATION_UI!$B$4:$B$8,"*FR2.6*")+COUNTIF(ADMIN_PORTAL!$B$4:$B$19,"*FR2.6*")+COUNTIF(BACKEND_API!$B$4:$B$23,"*FR2.6*") | E14: =IF(D14>=2,"Covered",IF(D14=1,"Minimal","GAP")) | F14: MED-09, API-15
A15: FR3.1 | B15: Accessibility | C15: Specialized UI modes based on disability type (visual accessibility for deaf users) | D15: =COUNTIF(AUTH!$B$4:$B$23,"*FR3.1*")+COUNTIF(PATIENT_SOS!$B$4:$B$21,"*FR3.1*")+COUNTIF(SECURITY_SOS!$B$4:$B$18,"*FR3.1*")+COUNTIF(RESPONDER!$B$4:$B$21,"*FR3.1*")+COUNTIF(CAREGIVER!$B$4:$B$15,"*FR3.1*")+COUNTIF(MEDICAL!$B$4:$B$14,"*FR3.1*")+COUNTIF(CHAT!$B$4:$B$17,"*FR3.1*")+COUNTIF(PRIVACY_CALLS!$B$4:$B$40,"*FR3.1*")+COUNTIF(PROFILE!$B$4:$B$9,"*FR3.1*")+COUNTIF(ACCESSIBILITY!$B$4:$B$22,"*FR3.1*")+COUNTIF(NOTIFICATIONS!$B$4:$B$19,"*FR3.1*")+COUNTIF(NAVIGATION_UI!$B$4:$B$8,"*FR3.1*")+COUNTIF(ADMIN_PORTAL!$B$4:$B$19,"*FR3.1*")+COUNTIF(BACKEND_API!$B$4:$B$23,"*FR3.1*") | E15: =IF(D15>=2,"Covered",IF(D15=1,"Minimal","GAP")) | F15: AUTH-02, SOS-02, SOS-07, SOS-08, CG-03, CHT-03, CHT-06, PHN-04, CALL-03, CALL-11, ACC-01, ACC-02, ACC-04, ACC-12
A16: FR3.2 | B16: Accessibility | C16: High-contrast themes + dynamic font scaling (up to 150%) | D16: =COUNTIF(AUTH!$B$4:$B$23,"*FR3.2*")+COUNTIF(PATIENT_SOS!$B$4:$B$21,"*FR3.2*")+COUNTIF(SECURITY_SOS!$B$4:$B$18,"*FR3.2*")+COUNTIF(RESPONDER!$B$4:$B$21,"*FR3.2*")+COUNTIF(CAREGIVER!$B$4:$B$15,"*FR3.2*")+COUNTIF(MEDICAL!$B$4:$B$14,"*FR3.2*")+COUNTIF(CHAT!$B$4:$B$17,"*FR3.2*")+COUNTIF(PRIVACY_CALLS!$B$4:$B$40,"*FR3.2*")+COUNTIF(PROFILE!$B$4:$B$9,"*FR3.2*")+COUNTIF(ACCESSIBILITY!$B$4:$B$22,"*FR3.2*")+COUNTIF(NOTIFICATIONS!$B$4:$B$19,"*FR3.2*")+COUNTIF(NAVIGATION_UI!$B$4:$B$8,"*FR3.2*")+COUNTIF(ADMIN_PORTAL!$B$4:$B$19,"*FR3.2*")+COUNTIF(BACKEND_API!$B$4:$B$23,"*FR3.2*") | E16: =IF(D16>=2,"Covered",IF(D16=1,"Minimal","GAP")) | F16: ACC-08, ACC-09, ACC-14
A17: FR3.3 | B17: Accessibility | C17: Haptic feedback for SOS countdowns and incoming messages | D17: =COUNTIF(AUTH!$B$4:$B$23,"*FR3.3*")+COUNTIF(PATIENT_SOS!$B$4:$B$21,"*FR3.3*")+COUNTIF(SECURITY_SOS!$B$4:$B$18,"*FR3.3*")+COUNTIF(RESPONDER!$B$4:$B$21,"*FR3.3*")+COUNTIF(CAREGIVER!$B$4:$B$15,"*FR3.3*")+COUNTIF(MEDICAL!$B$4:$B$14,"*FR3.3*")+COUNTIF(CHAT!$B$4:$B$17,"*FR3.3*")+COUNTIF(PRIVACY_CALLS!$B$4:$B$40,"*FR3.3*")+COUNTIF(PROFILE!$B$4:$B$9,"*FR3.3*")+COUNTIF(ACCESSIBILITY!$B$4:$B$22,"*FR3.3*")+COUNTIF(NOTIFICATIONS!$B$4:$B$19,"*FR3.3*")+COUNTIF(NAVIGATION_UI!$B$4:$B$8,"*FR3.3*")+COUNTIF(ADMIN_PORTAL!$B$4:$B$19,"*FR3.3*")+COUNTIF(BACKEND_API!$B$4:$B$23,"*FR3.3*") | E17: =IF(D17>=2,"Covered",IF(D17=1,"Minimal","GAP")) | F17: SOS-02, CG-06, CHT-10
A18: FR3.4 | B18: Accessibility | C18: Speech-impaired users operate without voice input — silent SOS + text communication | D18: =COUNTIF(AUTH!$B$4:$B$23,"*FR3.4*")+COUNTIF(PATIENT_SOS!$B$4:$B$21,"*FR3.4*")+COUNTIF(SECURITY_SOS!$B$4:$B$18,"*FR3.4*")+COUNTIF(RESPONDER!$B$4:$B$21,"*FR3.4*")+COUNTIF(CAREGIVER!$B$4:$B$15,"*FR3.4*")+COUNTIF(MEDICAL!$B$4:$B$14,"*FR3.4*")+COUNTIF(CHAT!$B$4:$B$17,"*FR3.4*")+COUNTIF(PRIVACY_CALLS!$B$4:$B$40,"*FR3.4*")+COUNTIF(PROFILE!$B$4:$B$9,"*FR3.4*")+COUNTIF(ACCESSIBILITY!$B$4:$B$22,"*FR3.4*")+COUNTIF(NOTIFICATIONS!$B$4:$B$19,"*FR3.4*")+COUNTIF(NAVIGATION_UI!$B$4:$B$8,"*FR3.4*")+COUNTIF(ADMIN_PORTAL!$B$4:$B$19,"*FR3.4*")+COUNTIF(BACKEND_API!$B$4:$B$23,"*FR3.4*") | E18: =IF(D18>=2,"Covered",IF(D18=1,"Minimal","GAP")) | F18: SOS-02, CHT-03, CHT-04, CHT-05, CHT-07, ACC-03, ACC-13
A19: FR3.5 | B19: Accessibility | C19: Large-scale buttons for motor impairment assistance | D19: =COUNTIF(AUTH!$B$4:$B$23,"*FR3.5*")+COUNTIF(PATIENT_SOS!$B$4:$B$21,"*FR3.5*")+COUNTIF(SECURITY_SOS!$B$4:$B$18,"*FR3.5*")+COUNTIF(RESPONDER!$B$4:$B$21,"*FR3.5*")+COUNTIF(CAREGIVER!$B$4:$B$15,"*FR3.5*")+COUNTIF(MEDICAL!$B$4:$B$14,"*FR3.5*")+COUNTIF(CHAT!$B$4:$B$17,"*FR3.5*")+COUNTIF(PRIVACY_CALLS!$B$4:$B$40,"*FR3.5*")+COUNTIF(PROFILE!$B$4:$B$9,"*FR3.5*")+COUNTIF(ACCESSIBILITY!$B$4:$B$22,"*FR3.5*")+COUNTIF(NOTIFICATIONS!$B$4:$B$19,"*FR3.5*")+COUNTIF(NAVIGATION_UI!$B$4:$B$8,"*FR3.5*")+COUNTIF(ADMIN_PORTAL!$B$4:$B$19,"*FR3.5*")+COUNTIF(BACKEND_API!$B$4:$B$23,"*FR3.5*") | E19: =IF(D19>=2,"Covered",IF(D19=1,"Minimal","GAP")) | F19: ACC-10, NAV-05
A20: FR4.1 | B20: SOS Emergency | C20: One-tap / long-press SOS button on home screen | D20: =COUNTIF(AUTH!$B$4:$B$23,"*FR4.1*")+COUNTIF(PATIENT_SOS!$B$4:$B$21,"*FR4.1*")+COUNTIF(SECURITY_SOS!$B$4:$B$18,"*FR4.1*")+COUNTIF(RESPONDER!$B$4:$B$21,"*FR4.1*")+COUNTIF(CAREGIVER!$B$4:$B$15,"*FR4.1*")+COUNTIF(MEDICAL!$B$4:$B$14,"*FR4.1*")+COUNTIF(CHAT!$B$4:$B$17,"*FR4.1*")+COUNTIF(PRIVACY_CALLS!$B$4:$B$40,"*FR4.1*")+COUNTIF(PROFILE!$B$4:$B$9,"*FR4.1*")+COUNTIF(ACCESSIBILITY!$B$4:$B$22,"*FR4.1*")+COUNTIF(NOTIFICATIONS!$B$4:$B$19,"*FR4.1*")+COUNTIF(NAVIGATION_UI!$B$4:$B$8,"*FR4.1*")+COUNTIF(ADMIN_PORTAL!$B$4:$B$19,"*FR4.1*")+COUNTIF(BACKEND_API!$B$4:$B$23,"*FR4.1*") | E20: =IF(D20>=2,"Covered",IF(D20=1,"Minimal","GAP")) | F20: SOS-01, SOS-12, SEC-01
A21: FR4.2 | B21: SOS Emergency | C21: Auto-capture and transmit high-accuracy GPS coordinates on SOS activation | D21: =COUNTIF(AUTH!$B$4:$B$23,"*FR4.2*")+COUNTIF(PATIENT_SOS!$B$4:$B$21,"*FR4.2*")+COUNTIF(SECURITY_SOS!$B$4:$B$18,"*FR4.2*")+COUNTIF(RESPONDER!$B$4:$B$21,"*FR4.2*")+COUNTIF(CAREGIVER!$B$4:$B$15,"*FR4.2*")+COUNTIF(MEDICAL!$B$4:$B$14,"*FR4.2*")+COUNTIF(CHAT!$B$4:$B$17,"*FR4.2*")+COUNTIF(PRIVACY_CALLS!$B$4:$B$40,"*FR4.2*")+COUNTIF(PROFILE!$B$4:$B$9,"*FR4.2*")+COUNTIF(ACCESSIBILITY!$B$4:$B$22,"*FR4.2*")+COUNTIF(NOTIFICATIONS!$B$4:$B$19,"*FR4.2*")+COUNTIF(NAVIGATION_UI!$B$4:$B$8,"*FR4.2*")+COUNTIF(ADMIN_PORTAL!$B$4:$B$19,"*FR4.2*")+COUNTIF(BACKEND_API!$B$4:$B$23,"*FR4.2*") | E21: =IF(D21>=2,"Covered",IF(D21=1,"Minimal","GAP")) | F21: SOS-04, SEC-03, SEC-05
A22: FR4.3 | B22: SOS Emergency | C22: Cancellation window with countdown timer (SRS: 10 s; implemented as 60 s by project decision) | D22: =COUNTIF(AUTH!$B$4:$B$23,"*FR4.3*")+COUNTIF(PATIENT_SOS!$B$4:$B$21,"*FR4.3*")+COUNTIF(SECURITY_SOS!$B$4:$B$18,"*FR4.3*")+COUNTIF(RESPONDER!$B$4:$B$21,"*FR4.3*")+COUNTIF(CAREGIVER!$B$4:$B$15,"*FR4.3*")+COUNTIF(MEDICAL!$B$4:$B$14,"*FR4.3*")+COUNTIF(CHAT!$B$4:$B$17,"*FR4.3*")+COUNTIF(PRIVACY_CALLS!$B$4:$B$40,"*FR4.3*")+COUNTIF(PROFILE!$B$4:$B$9,"*FR4.3*")+COUNTIF(ACCESSIBILITY!$B$4:$B$22,"*FR4.3*")+COUNTIF(NOTIFICATIONS!$B$4:$B$19,"*FR4.3*")+COUNTIF(NAVIGATION_UI!$B$4:$B$8,"*FR4.3*")+COUNTIF(ADMIN_PORTAL!$B$4:$B$19,"*FR4.3*")+COUNTIF(BACKEND_API!$B$4:$B$23,"*FR4.3*") | E22: =IF(D22>=2,"Covered",IF(D22=1,"Minimal","GAP")) | F22: SOS-01, SOS-03, SOS-14, SEC-02
A23: FR4.4 | B23: SOS Emergency | C23: Emergency categorization: Cardiac, Respiratory, Fall, Trauma, etc. | D23: =COUNTIF(AUTH!$B$4:$B$23,"*FR4.4*")+COUNTIF(PATIENT_SOS!$B$4:$B$21,"*FR4.4*")+COUNTIF(SECURITY_SOS!$B$4:$B$18,"*FR4.4*")+COUNTIF(RESPONDER!$B$4:$B$21,"*FR4.4*")+COUNTIF(CAREGIVER!$B$4:$B$15,"*FR4.4*")+COUNTIF(MEDICAL!$B$4:$B$14,"*FR4.4*")+COUNTIF(CHAT!$B$4:$B$17,"*FR4.4*")+COUNTIF(PRIVACY_CALLS!$B$4:$B$40,"*FR4.4*")+COUNTIF(PROFILE!$B$4:$B$9,"*FR4.4*")+COUNTIF(ACCESSIBILITY!$B$4:$B$22,"*FR4.4*")+COUNTIF(NOTIFICATIONS!$B$4:$B$19,"*FR4.4*")+COUNTIF(NAVIGATION_UI!$B$4:$B$8,"*FR4.4*")+COUNTIF(ADMIN_PORTAL!$B$4:$B$19,"*FR4.4*")+COUNTIF(BACKEND_API!$B$4:$B$23,"*FR4.4*") | E23: =IF(D23>=2,"Covered",IF(D23=1,"Minimal","GAP")) | F23: SOS-10
A24: FR4.5 | B24: SOS Emergency | C24: Notify all nearby available responders immediately | D24: =COUNTIF(AUTH!$B$4:$B$23,"*FR4.5*")+COUNTIF(PATIENT_SOS!$B$4:$B$21,"*FR4.5*")+COUNTIF(SECURITY_SOS!$B$4:$B$18,"*FR4.5*")+COUNTIF(RESPONDER!$B$4:$B$21,"*FR4.5*")+COUNTIF(CAREGIVER!$B$4:$B$15,"*FR4.5*")+COUNTIF(MEDICAL!$B$4:$B$14,"*FR4.5*")+COUNTIF(CHAT!$B$4:$B$17,"*FR4.5*")+COUNTIF(PRIVACY_CALLS!$B$4:$B$40,"*FR4.5*")+COUNTIF(PROFILE!$B$4:$B$9,"*FR4.5*")+COUNTIF(ACCESSIBILITY!$B$4:$B$22,"*FR4.5*")+COUNTIF(NOTIFICATIONS!$B$4:$B$19,"*FR4.5*")+COUNTIF(NAVIGATION_UI!$B$4:$B$8,"*FR4.5*")+COUNTIF(ADMIN_PORTAL!$B$4:$B$19,"*FR4.5*")+COUNTIF(BACKEND_API!$B$4:$B$23,"*FR4.5*") | E24: =IF(D24>=2,"Covered",IF(D24=1,"Minimal","GAP")) | F24: SOS-13, SEC-04, RSP-01, RSP-02, RSP-03, RSP-07, API-05
A25: FR4.6 | B25: SOS Emergency | C25: Notify all connected caregivers instantly | D25: =COUNTIF(AUTH!$B$4:$B$23,"*FR4.6*")+COUNTIF(PATIENT_SOS!$B$4:$B$21,"*FR4.6*")+COUNTIF(SECURITY_SOS!$B$4:$B$18,"*FR4.6*")+COUNTIF(RESPONDER!$B$4:$B$21,"*FR4.6*")+COUNTIF(CAREGIVER!$B$4:$B$15,"*FR4.6*")+COUNTIF(MEDICAL!$B$4:$B$14,"*FR4.6*")+COUNTIF(CHAT!$B$4:$B$17,"*FR4.6*")+COUNTIF(PRIVACY_CALLS!$B$4:$B$40,"*FR4.6*")+COUNTIF(PROFILE!$B$4:$B$9,"*FR4.6*")+COUNTIF(ACCESSIBILITY!$B$4:$B$22,"*FR4.6*")+COUNTIF(NOTIFICATIONS!$B$4:$B$19,"*FR4.6*")+COUNTIF(NAVIGATION_UI!$B$4:$B$8,"*FR4.6*")+COUNTIF(ADMIN_PORTAL!$B$4:$B$19,"*FR4.6*")+COUNTIF(BACKEND_API!$B$4:$B$23,"*FR4.6*") | E25: =IF(D25>=2,"Covered",IF(D25=1,"Minimal","GAP")) | F25: SOS-09, CG-05, CG-09
A26: FR5.1 | B26: Responder & Voice | C26: First responder to accept is atomically assigned — request closed for others | D26: =COUNTIF(AUTH!$B$4:$B$23,"*FR5.1*")+COUNTIF(PATIENT_SOS!$B$4:$B$21,"*FR5.1*")+COUNTIF(SECURITY_SOS!$B$4:$B$18,"*FR5.1*")+COUNTIF(RESPONDER!$B$4:$B$21,"*FR5.1*")+COUNTIF(CAREGIVER!$B$4:$B$15,"*FR5.1*")+COUNTIF(MEDICAL!$B$4:$B$14,"*FR5.1*")+COUNTIF(CHAT!$B$4:$B$17,"*FR5.1*")+COUNTIF(PRIVACY_CALLS!$B$4:$B$40,"*FR5.1*")+COUNTIF(PROFILE!$B$4:$B$9,"*FR5.1*")+COUNTIF(ACCESSIBILITY!$B$4:$B$22,"*FR5.1*")+COUNTIF(NOTIFICATIONS!$B$4:$B$19,"*FR5.1*")+COUNTIF(NAVIGATION_UI!$B$4:$B$8,"*FR5.1*")+COUNTIF(ADMIN_PORTAL!$B$4:$B$19,"*FR5.1*")+COUNTIF(BACKEND_API!$B$4:$B$23,"*FR5.1*") | E26: =IF(D26>=2,"Covered",IF(D26=1,"Minimal","GAP")) | F26: SEC-13, RSP-04, RSP-11, PRV-07, API-06
A27: FR5.2 | B27: Responder & Voice | C27: Hands-free Voice Alert via TTS reads patient details to responder | D27: =COUNTIF(AUTH!$B$4:$B$23,"*FR5.2*")+COUNTIF(PATIENT_SOS!$B$4:$B$21,"*FR5.2*")+COUNTIF(SECURITY_SOS!$B$4:$B$18,"*FR5.2*")+COUNTIF(RESPONDER!$B$4:$B$21,"*FR5.2*")+COUNTIF(CAREGIVER!$B$4:$B$15,"*FR5.2*")+COUNTIF(MEDICAL!$B$4:$B$14,"*FR5.2*")+COUNTIF(CHAT!$B$4:$B$17,"*FR5.2*")+COUNTIF(PRIVACY_CALLS!$B$4:$B$40,"*FR5.2*")+COUNTIF(PROFILE!$B$4:$B$9,"*FR5.2*")+COUNTIF(ACCESSIBILITY!$B$4:$B$22,"*FR5.2*")+COUNTIF(NOTIFICATIONS!$B$4:$B$19,"*FR5.2*")+COUNTIF(NAVIGATION_UI!$B$4:$B$8,"*FR5.2*")+COUNTIF(ADMIN_PORTAL!$B$4:$B$19,"*FR5.2*")+COUNTIF(BACKEND_API!$B$4:$B$23,"*FR5.2*") | E27: =IF(D27>=2,"Covered",IF(D27=1,"Minimal","GAP")) | F27: RSP-05, RSP-06, ACC-05
A28: FR5.3 | B28: Responder & Voice | C28: Voice alert includes emergency type, location, medical info, and DEAF status flag | D28: =COUNTIF(AUTH!$B$4:$B$23,"*FR5.3*")+COUNTIF(PATIENT_SOS!$B$4:$B$21,"*FR5.3*")+COUNTIF(SECURITY_SOS!$B$4:$B$18,"*FR5.3*")+COUNTIF(RESPONDER!$B$4:$B$21,"*FR5.3*")+COUNTIF(CAREGIVER!$B$4:$B$15,"*FR5.3*")+COUNTIF(MEDICAL!$B$4:$B$14,"*FR5.3*")+COUNTIF(CHAT!$B$4:$B$17,"*FR5.3*")+COUNTIF(PRIVACY_CALLS!$B$4:$B$40,"*FR5.3*")+COUNTIF(PROFILE!$B$4:$B$9,"*FR5.3*")+COUNTIF(ACCESSIBILITY!$B$4:$B$22,"*FR5.3*")+COUNTIF(NOTIFICATIONS!$B$4:$B$19,"*FR5.3*")+COUNTIF(NAVIGATION_UI!$B$4:$B$8,"*FR5.3*")+COUNTIF(ADMIN_PORTAL!$B$4:$B$19,"*FR5.3*")+COUNTIF(BACKEND_API!$B$4:$B$23,"*FR5.3*") | E28: =IF(D28>=2,"Covered",IF(D28=1,"Minimal","GAP")) | F28: RSP-05, PRV-03, PRV-04
A29: FR5.4 | B29: Responder & Voice | C29: Responders toggle availability (Online/Offline) | D29: =COUNTIF(AUTH!$B$4:$B$23,"*FR5.4*")+COUNTIF(PATIENT_SOS!$B$4:$B$21,"*FR5.4*")+COUNTIF(SECURITY_SOS!$B$4:$B$18,"*FR5.4*")+COUNTIF(RESPONDER!$B$4:$B$21,"*FR5.4*")+COUNTIF(CAREGIVER!$B$4:$B$15,"*FR5.4*")+COUNTIF(MEDICAL!$B$4:$B$14,"*FR5.4*")+COUNTIF(CHAT!$B$4:$B$17,"*FR5.4*")+COUNTIF(PRIVACY_CALLS!$B$4:$B$40,"*FR5.4*")+COUNTIF(PROFILE!$B$4:$B$9,"*FR5.4*")+COUNTIF(ACCESSIBILITY!$B$4:$B$22,"*FR5.4*")+COUNTIF(NOTIFICATIONS!$B$4:$B$19,"*FR5.4*")+COUNTIF(NAVIGATION_UI!$B$4:$B$8,"*FR5.4*")+COUNTIF(ADMIN_PORTAL!$B$4:$B$19,"*FR5.4*")+COUNTIF(BACKEND_API!$B$4:$B$23,"*FR5.4*") | E29: =IF(D29>=2,"Covered",IF(D29=1,"Minimal","GAP")) | F29: RSP-12
A30: FR6.1 | B30: Live Tracking | C30: Real-time responder location tracking via WebSockets | D30: =COUNTIF(AUTH!$B$4:$B$23,"*FR6.1*")+COUNTIF(PATIENT_SOS!$B$4:$B$21,"*FR6.1*")+COUNTIF(SECURITY_SOS!$B$4:$B$18,"*FR6.1*")+COUNTIF(RESPONDER!$B$4:$B$21,"*FR6.1*")+COUNTIF(CAREGIVER!$B$4:$B$15,"*FR6.1*")+COUNTIF(MEDICAL!$B$4:$B$14,"*FR6.1*")+COUNTIF(CHAT!$B$4:$B$17,"*FR6.1*")+COUNTIF(PRIVACY_CALLS!$B$4:$B$40,"*FR6.1*")+COUNTIF(PROFILE!$B$4:$B$9,"*FR6.1*")+COUNTIF(ACCESSIBILITY!$B$4:$B$22,"*FR6.1*")+COUNTIF(NOTIFICATIONS!$B$4:$B$19,"*FR6.1*")+COUNTIF(NAVIGATION_UI!$B$4:$B$8,"*FR6.1*")+COUNTIF(ADMIN_PORTAL!$B$4:$B$19,"*FR6.1*")+COUNTIF(BACKEND_API!$B$4:$B$23,"*FR6.1*") | E30: =IF(D30>=2,"Covered",IF(D30=1,"Minimal","GAP")) | F30: SOS-05, RSP-08, RSP-14, ADM-11, API-16
A31: FR6.2 | B31: Live Tracking | C31: Responder route + ETA displayed to Patient and Caregiver | D31: =COUNTIF(AUTH!$B$4:$B$23,"*FR6.2*")+COUNTIF(PATIENT_SOS!$B$4:$B$21,"*FR6.2*")+COUNTIF(SECURITY_SOS!$B$4:$B$18,"*FR6.2*")+COUNTIF(RESPONDER!$B$4:$B$21,"*FR6.2*")+COUNTIF(CAREGIVER!$B$4:$B$15,"*FR6.2*")+COUNTIF(MEDICAL!$B$4:$B$14,"*FR6.2*")+COUNTIF(CHAT!$B$4:$B$17,"*FR6.2*")+COUNTIF(PRIVACY_CALLS!$B$4:$B$40,"*FR6.2*")+COUNTIF(PROFILE!$B$4:$B$9,"*FR6.2*")+COUNTIF(ACCESSIBILITY!$B$4:$B$22,"*FR6.2*")+COUNTIF(NOTIFICATIONS!$B$4:$B$19,"*FR6.2*")+COUNTIF(NAVIGATION_UI!$B$4:$B$8,"*FR6.2*")+COUNTIF(ADMIN_PORTAL!$B$4:$B$19,"*FR6.2*")+COUNTIF(BACKEND_API!$B$4:$B$23,"*FR6.2*") | E31: =IF(D31>=2,"Covered",IF(D31=1,"Minimal","GAP")) | F31: SOS-06, SOS-11, SEC-06, RSP-08, RSP-09, RSP-10, CG-08, PERF-03, API-07
A32: FR6.3 | B32: Live Tracking | C32: Caregiver interactive map to monitor patient safety and location | D32: =COUNTIF(AUTH!$B$4:$B$23,"*FR6.3*")+COUNTIF(PATIENT_SOS!$B$4:$B$21,"*FR6.3*")+COUNTIF(SECURITY_SOS!$B$4:$B$18,"*FR6.3*")+COUNTIF(RESPONDER!$B$4:$B$21,"*FR6.3*")+COUNTIF(CAREGIVER!$B$4:$B$15,"*FR6.3*")+COUNTIF(MEDICAL!$B$4:$B$14,"*FR6.3*")+COUNTIF(CHAT!$B$4:$B$17,"*FR6.3*")+COUNTIF(PRIVACY_CALLS!$B$4:$B$40,"*FR6.3*")+COUNTIF(PROFILE!$B$4:$B$9,"*FR6.3*")+COUNTIF(ACCESSIBILITY!$B$4:$B$22,"*FR6.3*")+COUNTIF(NOTIFICATIONS!$B$4:$B$19,"*FR6.3*")+COUNTIF(NAVIGATION_UI!$B$4:$B$8,"*FR6.3*")+COUNTIF(ADMIN_PORTAL!$B$4:$B$19,"*FR6.3*")+COUNTIF(BACKEND_API!$B$4:$B$23,"*FR6.3*") | E32: =IF(D32>=2,"Covered",IF(D32=1,"Minimal","GAP")) | F32: CG-01, CG-08, API-13
A33: FR6.4 | B33: Live Tracking | C33: Navigation hooks for responders to reach patient exact location | D33: =COUNTIF(AUTH!$B$4:$B$23,"*FR6.4*")+COUNTIF(PATIENT_SOS!$B$4:$B$21,"*FR6.4*")+COUNTIF(SECURITY_SOS!$B$4:$B$18,"*FR6.4*")+COUNTIF(RESPONDER!$B$4:$B$21,"*FR6.4*")+COUNTIF(CAREGIVER!$B$4:$B$15,"*FR6.4*")+COUNTIF(MEDICAL!$B$4:$B$14,"*FR6.4*")+COUNTIF(CHAT!$B$4:$B$17,"*FR6.4*")+COUNTIF(PRIVACY_CALLS!$B$4:$B$40,"*FR6.4*")+COUNTIF(PROFILE!$B$4:$B$9,"*FR6.4*")+COUNTIF(ACCESSIBILITY!$B$4:$B$22,"*FR6.4*")+COUNTIF(NOTIFICATIONS!$B$4:$B$19,"*FR6.4*")+COUNTIF(NAVIGATION_UI!$B$4:$B$8,"*FR6.4*")+COUNTIF(ADMIN_PORTAL!$B$4:$B$19,"*FR6.4*")+COUNTIF(BACKEND_API!$B$4:$B$23,"*FR6.4*") | E33: =IF(D33>=2,"Covered",IF(D33=1,"Minimal","GAP")) | F33: RSP-13
A34: FR7.1 | B34: Chat | C34: Secure real-time chat between Patients and Caregivers via Socket.io | D34: =COUNTIF(AUTH!$B$4:$B$23,"*FR7.1*")+COUNTIF(PATIENT_SOS!$B$4:$B$21,"*FR7.1*")+COUNTIF(SECURITY_SOS!$B$4:$B$18,"*FR7.1*")+COUNTIF(RESPONDER!$B$4:$B$21,"*FR7.1*")+COUNTIF(CAREGIVER!$B$4:$B$15,"*FR7.1*")+COUNTIF(MEDICAL!$B$4:$B$14,"*FR7.1*")+COUNTIF(CHAT!$B$4:$B$17,"*FR7.1*")+COUNTIF(PRIVACY_CALLS!$B$4:$B$40,"*FR7.1*")+COUNTIF(PROFILE!$B$4:$B$9,"*FR7.1*")+COUNTIF(ACCESSIBILITY!$B$4:$B$22,"*FR7.1*")+COUNTIF(NOTIFICATIONS!$B$4:$B$19,"*FR7.1*")+COUNTIF(NAVIGATION_UI!$B$4:$B$8,"*FR7.1*")+COUNTIF(ADMIN_PORTAL!$B$4:$B$19,"*FR7.1*")+COUNTIF(BACKEND_API!$B$4:$B$23,"*FR7.1*") | E34: =IF(D34>=2,"Covered",IF(D34=1,"Minimal","GAP")) | F34: CHT-01, CHT-02
A35: FR7.2 | B35: Chat | C35: Many-to-many: one patient to many caregivers; one caregiver to many patients | D35: =COUNTIF(AUTH!$B$4:$B$23,"*FR7.2*")+COUNTIF(PATIENT_SOS!$B$4:$B$21,"*FR7.2*")+COUNTIF(SECURITY_SOS!$B$4:$B$18,"*FR7.2*")+COUNTIF(RESPONDER!$B$4:$B$21,"*FR7.2*")+COUNTIF(CAREGIVER!$B$4:$B$15,"*FR7.2*")+COUNTIF(MEDICAL!$B$4:$B$14,"*FR7.2*")+COUNTIF(CHAT!$B$4:$B$17,"*FR7.2*")+COUNTIF(PRIVACY_CALLS!$B$4:$B$40,"*FR7.2*")+COUNTIF(PROFILE!$B$4:$B$9,"*FR7.2*")+COUNTIF(ACCESSIBILITY!$B$4:$B$22,"*FR7.2*")+COUNTIF(NOTIFICATIONS!$B$4:$B$19,"*FR7.2*")+COUNTIF(NAVIGATION_UI!$B$4:$B$8,"*FR7.2*")+COUNTIF(ADMIN_PORTAL!$B$4:$B$19,"*FR7.2*")+COUNTIF(BACKEND_API!$B$4:$B$23,"*FR7.2*") | E35: =IF(D35>=2,"Covered",IF(D35=1,"Minimal","GAP")) | F35: CG-01, CG-07, CHT-08
A36: FR7.3 | B36: Chat | C36: Private chat silos — messages in one room never visible to others | D36: =COUNTIF(AUTH!$B$4:$B$23,"*FR7.3*")+COUNTIF(PATIENT_SOS!$B$4:$B$21,"*FR7.3*")+COUNTIF(SECURITY_SOS!$B$4:$B$18,"*FR7.3*")+COUNTIF(RESPONDER!$B$4:$B$21,"*FR7.3*")+COUNTIF(CAREGIVER!$B$4:$B$15,"*FR7.3*")+COUNTIF(MEDICAL!$B$4:$B$14,"*FR7.3*")+COUNTIF(CHAT!$B$4:$B$17,"*FR7.3*")+COUNTIF(PRIVACY_CALLS!$B$4:$B$40,"*FR7.3*")+COUNTIF(PROFILE!$B$4:$B$9,"*FR7.3*")+COUNTIF(ACCESSIBILITY!$B$4:$B$22,"*FR7.3*")+COUNTIF(NOTIFICATIONS!$B$4:$B$19,"*FR7.3*")+COUNTIF(NAVIGATION_UI!$B$4:$B$8,"*FR7.3*")+COUNTIF(ADMIN_PORTAL!$B$4:$B$19,"*FR7.3*")+COUNTIF(BACKEND_API!$B$4:$B$23,"*FR7.3*") | E36: =IF(D36>=2,"Covered",IF(D36=1,"Minimal","GAP")) | F36: CHT-09, PRV-01, PRV-02, LCK-01
A37: FR7.4 | B37: Chat | C37: Instant message notifications with haptic alerts | D37: =COUNTIF(AUTH!$B$4:$B$23,"*FR7.4*")+COUNTIF(PATIENT_SOS!$B$4:$B$21,"*FR7.4*")+COUNTIF(SECURITY_SOS!$B$4:$B$18,"*FR7.4*")+COUNTIF(RESPONDER!$B$4:$B$21,"*FR7.4*")+COUNTIF(CAREGIVER!$B$4:$B$15,"*FR7.4*")+COUNTIF(MEDICAL!$B$4:$B$14,"*FR7.4*")+COUNTIF(CHAT!$B$4:$B$17,"*FR7.4*")+COUNTIF(PRIVACY_CALLS!$B$4:$B$40,"*FR7.4*")+COUNTIF(PROFILE!$B$4:$B$9,"*FR7.4*")+COUNTIF(ACCESSIBILITY!$B$4:$B$22,"*FR7.4*")+COUNTIF(NOTIFICATIONS!$B$4:$B$19,"*FR7.4*")+COUNTIF(NAVIGATION_UI!$B$4:$B$8,"*FR7.4*")+COUNTIF(ADMIN_PORTAL!$B$4:$B$19,"*FR7.4*")+COUNTIF(BACKEND_API!$B$4:$B$23,"*FR7.4*") | E37: =IF(D37>=2,"Covered",IF(D37=1,"Minimal","GAP")) | F37: CHT-10, NTF-06
A38: FR7.5 | B38: Chat | C38: Persistent chat history for continuity of care | D38: =COUNTIF(AUTH!$B$4:$B$23,"*FR7.5*")+COUNTIF(PATIENT_SOS!$B$4:$B$21,"*FR7.5*")+COUNTIF(SECURITY_SOS!$B$4:$B$18,"*FR7.5*")+COUNTIF(RESPONDER!$B$4:$B$21,"*FR7.5*")+COUNTIF(CAREGIVER!$B$4:$B$15,"*FR7.5*")+COUNTIF(MEDICAL!$B$4:$B$14,"*FR7.5*")+COUNTIF(CHAT!$B$4:$B$17,"*FR7.5*")+COUNTIF(PRIVACY_CALLS!$B$4:$B$40,"*FR7.5*")+COUNTIF(PROFILE!$B$4:$B$9,"*FR7.5*")+COUNTIF(ACCESSIBILITY!$B$4:$B$22,"*FR7.5*")+COUNTIF(NOTIFICATIONS!$B$4:$B$19,"*FR7.5*")+COUNTIF(NAVIGATION_UI!$B$4:$B$8,"*FR7.5*")+COUNTIF(ADMIN_PORTAL!$B$4:$B$19,"*FR7.5*")+COUNTIF(BACKEND_API!$B$4:$B$23,"*FR7.5*") | E38: =IF(D38>=2,"Covered",IF(D38=1,"Minimal","GAP")) | F38: CHT-11
A39: FR8.1 | B39: UI & Navigation | C39: Unified Sidebar (AppDrawer) navigation | D39: =COUNTIF(AUTH!$B$4:$B$23,"*FR8.1*")+COUNTIF(PATIENT_SOS!$B$4:$B$21,"*FR8.1*")+COUNTIF(SECURITY_SOS!$B$4:$B$18,"*FR8.1*")+COUNTIF(RESPONDER!$B$4:$B$21,"*FR8.1*")+COUNTIF(CAREGIVER!$B$4:$B$15,"*FR8.1*")+COUNTIF(MEDICAL!$B$4:$B$14,"*FR8.1*")+COUNTIF(CHAT!$B$4:$B$17,"*FR8.1*")+COUNTIF(PRIVACY_CALLS!$B$4:$B$40,"*FR8.1*")+COUNTIF(PROFILE!$B$4:$B$9,"*FR8.1*")+COUNTIF(ACCESSIBILITY!$B$4:$B$22,"*FR8.1*")+COUNTIF(NOTIFICATIONS!$B$4:$B$19,"*FR8.1*")+COUNTIF(NAVIGATION_UI!$B$4:$B$8,"*FR8.1*")+COUNTIF(ADMIN_PORTAL!$B$4:$B$19,"*FR8.1*")+COUNTIF(BACKEND_API!$B$4:$B$23,"*FR8.1*") | E39: =IF(D39>=2,"Covered",IF(D39=1,"Minimal","GAP")) | F39: NAV-01
A40: FR8.2 | B40: UI & Navigation | C40: StatefulShellRoute — preserves navigation history, no UI flickering | D40: =COUNTIF(AUTH!$B$4:$B$23,"*FR8.2*")+COUNTIF(PATIENT_SOS!$B$4:$B$21,"*FR8.2*")+COUNTIF(SECURITY_SOS!$B$4:$B$18,"*FR8.2*")+COUNTIF(RESPONDER!$B$4:$B$21,"*FR8.2*")+COUNTIF(CAREGIVER!$B$4:$B$15,"*FR8.2*")+COUNTIF(MEDICAL!$B$4:$B$14,"*FR8.2*")+COUNTIF(CHAT!$B$4:$B$17,"*FR8.2*")+COUNTIF(PRIVACY_CALLS!$B$4:$B$40,"*FR8.2*")+COUNTIF(PROFILE!$B$4:$B$9,"*FR8.2*")+COUNTIF(ACCESSIBILITY!$B$4:$B$22,"*FR8.2*")+COUNTIF(NOTIFICATIONS!$B$4:$B$19,"*FR8.2*")+COUNTIF(NAVIGATION_UI!$B$4:$B$8,"*FR8.2*")+COUNTIF(ADMIN_PORTAL!$B$4:$B$19,"*FR8.2*")+COUNTIF(BACKEND_API!$B$4:$B$23,"*FR8.2*") | E40: =IF(D40>=2,"Covered",IF(D40=1,"Minimal","GAP")) | F40: CG-02, NAV-02
...

Sheet AUTH
A1: MediFind — AUTH Requirements & Test Cases
A2: REQ ID | B2: SRS Ref | C2: Module | D2: Requirement Description | E2: Test Steps | F2: Expected Result | G2: Priority | H2: Status | I2: Notes / Defect Ref
A3: REGISTRATION
A4: AUTH-01 | B4: FR1.1, FR1.3 | C4: Registration | D4: Patient can register with name, email, password, phone, CNIC number and patient type (Normal/Deaf) | E4: 1. Open app → Get started 2. Choose Patient → "I can hear" 3. Fill name, email, phone, CNIC, password (8+) 4. Submit | F4: HTTP 201; OTP verification screen shown; 6-digit code emailed (valid 15 min) | G4: Critical | H4: PENDING
A5: AUTH-02 | B5: FR1.1, FR3.1 | C5: Registration | D5: Deaf patient can register with patientType = DEAF | E5: 1. Register with patientType = DEAF 2. Complete all steps | F5: Account created; deaf-specific onboarding tips shown; textOnlyMode defaults to true | G5: Critical | H5: PENDING
A6: AUTH-03 | B6: FR1.1, FR9.4 | C6: Registration | D6: Responder can register with CNIC (front/back), employee card, driving licence and motorbike documents | E6: 1. Choose Responder 2. Fill organisation, licence no., motorbike no. 3. Upload all documents 4. Submit | F6: Account created with verification PENDING; "Awaiting admin approval" screen; application appears in admin Verification Queue | G6: Critical | H6: PENDING
A7: AUTH-04 | B7: FR1.1, FR1.3 | C7: Registration | D7: Caregiver can register; linking to a patient happens after login by email invitation | E7: 1. Choose Caregiver 2. Complete registration and email OTP 3. Log in → Link patient → enter patient email | F7: Caregiver account created; invitation sent to patient (in-app + push + email); link shows PENDING until patient accepts | G7: High | H7: PENDING
A8: AUTH-05 | B8: FR1.1 | C8: Registration | D8: Duplicate email registration is rejected | E8: 1. Register with an email already in the system 2. Submit | F8: Error "User already exists with this email" shown; no duplicate account created | G8: High | H8: PENDING
A9: AUTH-06 | B9: FR1.1 | C9: Registration | D9: Password must meet minimum requirements (≥8 chars) | E9: 1. Enter password with 5 characters 2. Submit | F9: Validation error shown inline; form not submitted | G9: Medium | H9: PENDING
A10: LOGIN
A11: AUTH-07 | B11: FR1.2, FR1.6 | C11: Login | D11: Registered user can log in with email and password | E11: 1. Enter valid credentials 2. Tap Login | F11: JWT token stored; user navigated to role-appropriate home screen | G11: Critical | H11: PENDING
A12: AUTH-08 | B12: FR1.2 | C12: Login | D12: Invalid credentials show an error and do not log in | E12: 1. Enter wrong password 2. Tap Login | F12: Error "Invalid credentials" shown; user stays on login; warning appears when 2 or fewer attempts remain | G12: Critical | H12: PENDING
A13: AUTH-09 | B13: FR1.2 | C13: Login | D13: Unverified account is blocked from logging in | E13: 1. Register new account but do not verify email 2. Try to log in | F13: Login denied with "Please verify your email before logging in"; OTP screen offered | G13: High | H13: PENDING
A14: SESSION & LOGOUT
A15: AUTH-10 | B15: FR1.2 | C15: Session | D15: JWT token is refreshed before expiry | E15: 1. Log in 2. Wait 29 minutes (near 30-min access token expiry) 3. Perform any API action | F15: Token refreshed silently; user remains logged in without interruption | G15: High | H15: PENDING
A16: AUTH-11 | B16: FR1.2 | C16: Logout | D16: User can log out; session is fully cleared | E16: 1. Log in 2. Navigate to Settings 3. Tap Logout | F16: Tokens cleared from storage; user redirected to Login screen; back button does not return to protected screen | G16: High | H16: PENDING
A17: AUTH-12 | B17: Beyond SRS | C17: Logout | D17: After account deletion, user is redirected to Login screen without black screen flash | E17: 1. Log in as any role 2. Go to Profile Settings 3. Tap Delete Account 4. Confirm in dialog | F17: Account deleted; user redirected smoothly to Login screen; NO black screen / dark overlay flash during transition | G17: Critical | H17: PENDING
A18: ADDED IN v2.0 — SRS GAPS & NEW FEATURES
A19: AUTH-13 | B19: FR1.2 | C19: Login | D19: Account locks for 30 minutes after 5 failed login attempts | E19: 1. Enter wrong password 5 times 2. Enter correct password | F19: Locked message with minutes remaining; correct password rejected until lock expires | G19: High | H19: PENDING
A20: AUTH-14 | B20: FR1.5 | C20: Password Reset | D20: User resets a forgotten password with an emailed 6-digit OTP | E20: 1. Login → Forgot password → enter email 2. Enter OTP from email 3. Set new password (8+) | F20: Password changed; old sessions signed out; login works with new password only | G20: Critical | H20: PENDING
A21: AUTH-15 | B21: FR1.5 | C21: Password Reset | D21: Reset/verification code is invalidated after 5 wrong attempts | E21: 1. Request reset code 2. Enter a wrong code 5 times 3. Enter the correct code | F21: After 5 wrong attempts: "Too many incorrect attempts"; the old code no longer works; a new code must be requested | G21: High | H21: PENDING
A22: AUTH-16 | B22: FR1.4, FR1.6 | C22: Registration | D22: Public registration cannot create an ADMIN account | E22: POST /api/auth/register with role = ADMIN | F22: HTTP 400 "Invalid role"; no account created | G22: Critical | H22: PENDING
A23: AUTH-17 | B23: FR9.3 | C23: Login | D23: Deactivated account cannot log in and existing sessions stop working | E23: 1. Admin deactivates a logged-in user 2. User performs any action 3. User tries to log in again | F23: API returns 401 "account has been deactivated"; app signs out; login denied | G23: High | H23: PENDING

Sheet PATIENT_SOS
A1: MediFind — PATIENT_SOS Requirements & Test Cases
A2: REQ ID | B2: SRS Ref | C2: Module | D2: Requirement Description | E2: Test Steps | F2: Expected Result | G2: Priority | H2: Status | I2: Notes / Defect Ref
A3: SOS TRIGGER
A4: SOS-01 | B4: FR4.1, FR4.3 | C4: SOS Trigger | D4: Patient triggers SOS by holding the SOS button, choosing an emergency type, then a 60-second countdown before the alert is sent | E4: 1. Press and hold SOS for ~2 s (progress ring fills) 2. Select emergency type 3. Watch the 60-second countdown reach 0 (or tap Send SOS now) | F4: No request is sent during the countdown; at 0 the SOS is created (HTTP 201), patient enters searching/tracking screen, nearby responders notified | G4: Critical | H4: PENDING
A5: SOS-02 | B5: FR3.1, FR3.3, FR3.4 | C5: SOS Trigger | D5: Deaf patient can trigger SOS — no voice prompt plays during countdown or after submission | E5: 1. Log in as Deaf Patient 2. Trigger SOS 3. Confirm 4. Monitor for any audio output | F5: SOS triggered; NO TTS voice plays; vibration feedback fires if enabled; full-screen visual confirmation shown | G5: Critical | H5: PENDING
A6: SOS-03 | B6: FR4.3 | C6: SOS Trigger | D6: SOS can be cancelled during the 60-second countdown without contacting the server | E6: 1. Start SOS (hold + type) 2. Tap Cancel before the countdown ends 3. Check admin SOS Logistics | F6: Countdown stops; user returns to Home; NO emergency record exists and no responder/caregiver is notified | G6: High | H6: PENDING
A7: SOS-04 | B7: FR4.2 | C7: SOS Trigger | D7: GPS/location permission is required; the app never sends a fake or default location | E7: 1. Disable location permission or GPS 2. Try to send SOS | F7: Prompt to enable location with "Open settings", "Try again" and "Call 1122"; SOS is not sent without a real fix | G7: High | H7: PENDING
A8: EMERGENCY TRACKING
A9: SOS-05 | B9: FR6.1 | C9: Tracking | D9: Patient sees live responder location on map after responder accepts | E9: 1. Trigger SOS 2. Accept from a logged-in Responder account 3. Observe patient tracking screen | F9: Responder pin appears on map; pin updates every few seconds as responder moves | G9: Critical | H9: PENDING
A10: SOS-06 | B10: FR6.2 | C10: Tracking | D10: Status updates (ASSIGNED → EN_ROUTE → ARRIVED) shown on tracking screen | E10: Trigger SOS → responder accepts → marks En route → Arrived → Resolves | F10: Tracking screen timeline updates in real time: Assigned → En route → Arrived → Resolved | G10: Critical | H10: PENDING
A11: SOS-07 | B11: FR3.1 | C11: Tracking | D11: Normal patient receives voice status updates (TTS) when voiceGuidance is ON | E11: 1. Enable Voice Guidance in Accessibility Settings 2. Trigger SOS 3. Responder changes status | F11: TTS speaks "A responder has been assigned and is on the way" and subsequent status messages | G11: High | H11: PENDING
A12: SOS-08 | B12: FR3.1 | C12: Tracking | D12: Deaf patient does NOT receive TTS status updates regardless of settings | E12: 1. Log in as Deaf Patient 2. Trigger SOS 3. Responder changes status 4. Monitor for audio | F12: No TTS plays; visual status banner updates; vibration fires if enabled | G12: High | H12: PENDING
A13: SOS-09 | B13: FR4.6 | C13: Tracking | D13: Caregiver receives notification when their linked patient triggers SOS | E13: 1. Log in as Caregiver linked to a patient 2. Trigger SOS from patient account 3. Check Caregiver device | F13: Push notification and in-app alert received by caregiver | G13: High | H13: PENDING
A14: ADDED IN v2.0 — SRS GAPS & NEW FEATURES
A15: SOS-10 | B15: FR4.4 | C15: SOS Trigger | D15: Patient selects a medical emergency category | E15: 1. Start SOS 2. Review type options | F15: Options: Cardiac, Stroke, Breathing, Trauma, Fall, Seizure, Diabetic, Other (medical only); chosen type shown to responder | G15: High | H15: PENDING
A16: SOS-11 | B16: FR6.2 | C16: Tracking | D16: Patient sees responder ETA that updates while the responder moves | E16: 1. Responder accepts and drives toward patient | F16: ETA (minutes) visible on tracking screen and decreases as responder approaches | G16: High | H16: PENDING
A17: SOS-12 | B17: FR4.1 | C17: SOS Trigger | D17: A quick accidental tap on SOS does not start an emergency | E17: 1. Tap SOS briefly (< 1 s) | F17: No countdown starts; hint "Press and hold to send SOS" shown | G17: Critical | H17: PENDING
A18: SOS-13 | B18: FR4.5 | C18: SOS Trigger | D18: A second SOS while one is open returns the existing emergency (no duplicate dispatch) | E18: 1. Send SOS 2. Send SOS again before it closes | F18: HTTP 200 with alreadyActive = true and the same emergency id; responders are not notified twice | G18: High | H18: PASS | I18: 2026-09-17: second SOS returned the same emergency id (alreadyActive), no second dispatch
A19: SOS-14 | B19: FR4.3 | C19: Cancellation | D19: After sending, the patient can still cancel within the server cancellation window | E19: 1. Let countdown finish (SOS sent) 2. Tap Cancel on searching screen before a responder accepts | F19: Emergency CANCELLED; notified responders see the alert removed; not counted as a false alarm | G19: High | H19: PENDING
A20: SOS-15 | B20: Beyond SRS | C20: Offline | D20: Offline patient can still call or SMS Rescue 1122 | E20: 1. Turn off internet 2. Open SOS | F20: Non-blocking offline banner with working Call 1122 and SMS 1122 buttons | G20: High | H20: PENDING
A21: SOS-16 | B21: Beyond SRS | C21: Rating | D21: Patient rates the responder after resolution (once) | E21: 1. Emergency resolved 2. Give 5 stars 3. Try to rate again | F21: Rating saved and responder average updated; second rating rejected | G21: Medium | H21: PENDING

Sheet SECURITY_SOS
A1: MediFind — SECURITY_SOS Requirements & Test Cases
A2: REQ ID | B2: SRS Ref | C2: Module | D2: Requirement Description | E2: Test Steps | F2: Expected Result | G2: Priority | H2: Status | I2: Notes / Defect Ref
A3: FALSE SOS PREVENTION
A4: SEC-01 | B4: FR4.1 | C4: Trigger | D4: SOS requires press-and-hold before it starts | E4: 1. Tap SOS 2. Hold SOS for 2 s | F4: Tap: nothing sent, hint shown. Hold: countdown starts with progress ring and vibration | G4: Critical | H4: PENDING
A5: SEC-02 | B5: FR4.3 | C5: Countdown | D5: Cancelling during the 60-second countdown sends nothing to the server | E5: Start SOS and cancel at 30 s | F5: No emergency record, no notifications | G5: Critical | H5: PASS | I5: 2026-09-17: cancelling in the countdown created 0 emergency rows and 0 notifications (API/DB check)
A6: SEC-03 | B6: FR4.2 | C6: Location | D6: SOS from a mock (fake) GPS location is refused in production | E6: Enable a mock location app and send SOS (production build) | F6: HTTP 422 "fake (mock) GPS location" with Call 1122 advice; no dispatch | G6: Critical | H6: PENDING
A7: SEC-04 | B7: FR4.5 | C7: Rate limit | D7: More than 5 SOS in one hour is refused | E7: Send and cancel SOS 5 times, then send a 6th | F7: 6th request: HTTP 429 "Too many SOS requests" with Call 1122 advice | G7: High | H7: PASS | I7: 2026-09-17: 6th SOS within an hour returned HTTP 429 with Call 1122 advice
A8: SEC-05 | B8: FR4.2 | C8: Location | D8: SOS outside Pakistan coordinates is refused | E8: POST /api/emergencies with Dubai coordinates | F8: HTTP 400 with coordinate error | G8: Medium | H8: PASS | I8: 2026-09-17: SOS with coordinates outside Pakistan returned HTTP 400
A9: FALSE ALARM HANDLING
A10: SEC-06 | B10: FR6.2 | C10: Resolve | D10: Responder must add a note when closing as False alarm or Patient not found | E10: Resolve with outcome FALSE_ALARM and empty note | F10: HTTP 400 "Please add a short note"; with a note the emergency closes with outcome saved | G10: High | H10: PENDING
A11: SEC-07 | B11: Beyond SRS | C11: Warning | D11: Patient is warned when an SOS is marked as a false alarm | E11: Responder resolves as FALSE_ALARM | F11: Patient receives "SOS marked as false alarm" notification | G11: High | H11: PENDING
A12: SEC-08 | B12: Beyond SRS | C12: Review | D12: 3 false alarms in 30 days alerts admins for review | E12: Mark 3 SOS from the same patient as FALSE_ALARM | F12: Admins receive "Patient flagged for repeated false SOS"; admin user profile shows the count | G12: High | H12: PENDING
A13: SEC-09 | B13: Beyond SRS | C13: Fairness | D13: Patient-cancelled SOS never counts as a false alarm | E13: Cancel 3 SOS within the window | F13: False alarm count stays 0; no admin alert | G13: Medium | H13: PENDING
A14: PLATFORM SECURITY
A15: SEC-10 | B15: FR1.6 | C15: Tokens | D15: Refresh token cannot be used as an access token | E15: Call a protected API with the refresh token as Bearer | F15: HTTP 401 | G15: Critical | H15: PENDING
A16: SEC-11 | B16: FR1.6 | C16: Sockets | D16: Users cannot join emergency or chat rooms they do not belong to | E16: Emit join:emergency / join:chat for another user's ids | F16: Join refused; no events received | G16: Critical | H16: PENDING
A17: SEC-12 | B17: Beyond SRS | C17: Payments | D17: Paid plan upgrade requires a verified Stripe payment | E17: PATCH /api/users/upgrade {plan: EXECUTIVE} without paymentIntentId | F17: HTTP 402; plan unchanged | G17: High | H17: PENDING
A18: SEC-13 | B18: FR5.1 | C18: Emergency | D18: Only the assigned responder can update or resolve an emergency | E18: Another responder calls status/resolve | F18: HTTP 403 / 400; emergency unchanged | G18: Critical | H18: PENDING

Sheet RESPONDER
A1: MediFind — RESPONDER Requirements & Test Cases
A2: REQ ID | B2: SRS Ref | C2: Module | D2: Requirement Description | E2: Test Steps | F2: Expected Result | G2: Priority | H2: Status | I2: Notes / Defect Ref
A3: INCOMING EMERGENCY ALERTS
A4: RSP-01 | B4: FR4.5 | C4: Alert Receipt | D4: Verified, available responder within 10 km receives the SOS alert in real time | E4: 1. Responder online (availability ON) 2. Patient within 10 km sends SOS | F4: Alert card on Responder home and a push notification (even when the app is closed) within ~2 s | G4: Critical | H4: PENDING
A5: RSP-02 | B5: FR2.5, FR4.5 | C5: Alert Receipt | D5: Alert shows patient name, emergency type, distance, ETA, DEAF badge and key medical flags | E5: 1. Receive emergency alert 2. Inspect alert card | F5: Card shows name, type, distance (km), ETA, DEAF badge if applicable, blood group/allergy badges | G5: High | H5: PENDING
A6: RSP-03 | B6: FR4.5, FR9.4 | C6: Alert Receipt | D6: Unverified responder does NOT receive emergency alerts | E6: 1. Log in as PENDING/unverified Responder 2. Trigger SOS from patient | F6: No alert received; unverified responder not included in dispatch | G6: High | H6: PENDING
A7: ACCEPT / REJECT
A8: RSP-04 | B8: FR5.1 | C8: Accept | D8: Responder can accept emergency; patient tracking screen reflects ASSIGNED status | E8: 1. Receive alert 2. Tap Accept 3. Check patient tracking screen | F8: Status changes to ASSIGNED on patient screen; responder enters Active Emergency screen | G8: Critical | H8: PENDING
A9: RSP-05 | B9: FR5.2, FR5.3 | C9: Accept | D9: On accept, Voice Alert auto-plays patient details if voiceGuidanceEnabled is ON | E9: 1. Enable Hands-Free Voice Alerts in Accessibility Settings 2. Accept emergency | F9: TTS reads emergency type, location, allergies, blood group and the DEAF flag ("patient is deaf — communicate by text") | G9: High | H9: PENDING
A10: RSP-06 | B10: FR5.2 | C10: Accept | D10: On accept, NO auto-play voice if voiceGuidanceEnabled is OFF | E10: 1. Disable Hands-Free Voice Alerts 2. Accept emergency | F10: No TTS plays automatically; manual "Play Voice Alert" button still works | G10: High | H10: PENDING
A11: RSP-07 | B11: FR4.5 | C11: Reject | D11: Responder can reject; the SOS remains available to other notified responders and is re-dispatched if nobody accepts | E11: 1. Two responders receive the same SOS 2. Responder A rejects 3. Wait 60 s without any accept | F11: Alert removed only for A; B can still accept; after 60 s without accept the SOS is re-dispatched and admin receives an escalation alert | G11: Medium | H11: PENDING
A12: STATUS UPDATES
A13: RSP-08 | B13: FR6.1, FR6.2 | C13: Status | D13: Responder can mark EN_ROUTE; patient sees update | E13: 1. Accept emergency 2. Tap "On the Way" 3. Check patient screen | F13: Patient tracking screen shows EN_ROUTE status | G13: Critical | H13: PENDING
A14: RSP-09 | B14: FR6.2 | C14: Status | D14: Responder marks ARRIVED; patient and caregivers are notified; the emergency stays open until the responder resolves it | E14: 1. Accept SOS 2. Mark En route → Arrived | F14: Patient sees "Help has arrived"; caregivers get an update (not a new SOS alert); status ARRIVED until Resolve | G14: Critical | H14: PENDING
A15: ADDED IN v2.0 — SRS GAPS & NEW FEATURES
A16: RSP-10 | B16: FR6.2 | C16: Status | D16: Responder resolves the emergency with an outcome | E16: 1. After arrival tap Resolve 2. Choose Treated on site | F16: Emergency RESOLVED with outcome saved; responder becomes available; patient asked to rate | G16: Critical | H16: PENDING
A17: RSP-11 | B17: FR5.1 | C17: Accept | D17: Only one of two simultaneous accepts succeeds | E17: 1. Two responders tap Accept at the same moment | F17: One responder enters Active Emergency; the other sees "already assigned" and the alert disappears | G17: Critical | H17: PENDING
A18: RSP-12 | B18: FR5.4 | C18: Availability | D18: Offline responders are not dispatched | E18: 1. Toggle availability OFF 2. Patient nearby sends SOS 3. Toggle ON and repeat | F18: No alert while OFF; alert received after switching ON; toggle state persists after reopening the app | G18: High | H18: PENDING
A19: RSP-13 | B19: FR6.4 | C19: Navigation | D19: Navigate opens turn-by-turn directions to the patient | E19: 1. Active emergency → tap Navigate | F19: Google Maps opens with driving directions to the patient coordinates | G19: High | H19: PENDING
A20: RSP-14 | B20: FR6.1 | C20: Tracking | D20: Responder location is shared live every few seconds during an active emergency | E20: 1. Accept SOS 2. Move for 1 minute | F20: Patient, caregiver and admin live map show the motorbike ambulance moving smoothly | G20: Critical | H20: PENDING
A21: RSP-15 | B21: Beyond SRS | C21: Assignment | D21: Responder cancelling an accepted job re-dispatches the SOS | E21: 1. Accept SOS 2. Cancel response (confirm) | F21: Patient sees "Finding another responder"; other nearby responders receive the alert | G21: Medium | H21: PENDING

Sheet CAREGIVER
A1: MediFind — CAREGIVER Requirements & Test Cases
A2: REQ ID | B2: SRS Ref | C2: Module | D2: Requirement Description | E2: Test Steps | F2: Expected Result | G2: Priority | H2: Status | I2: Notes / Defect Ref
A3: LINKED PATIENTS
A4: CG-01 | B4: FR6.3, FR7.2 | C4: Linked Patients | D4: Caregiver can view list of all linked patients on home screen | E4: 1. Log in as Caregiver 2. Navigate to Home | F4: List of linked patients shown with name, status, and last active time | G4: High | H4: PENDING
A5: CG-02 | B5: FR8.2 | C5: Patient Profile | D5: Caregiver can open a linked patient's profile with visible header and back navigation | E5: 1. Log in as Caregiver 2. Tap a linked patient's card 3. Inspect the screen | F5: Profile opens with "Patient Profile" AppBar title visible; back arrow present; bottom nav NOT shown | G5: High | H5: PENDING
A6: CG-03 | B6: FR3.1 | C6: Patient Profile | D6: Deaf patient badge shown on patient profile with caregiver-relevant subtitle | E6: 1. View profile of a Deaf linked patient | F6: Deaf badge shows subtitle: "Communicate via text chat • Cannot receive voice calls • Uses visual alerts" | G6: Medium | H6: PENDING
A7: CG-04 | B7: FR1.6 | C7: Patient Profile | D7: Caregiver does NOT see the accessibility settings banner on patient profile | E7: 1. View a linked patient's profile 2. Check for accessibility banner | F7: No accessibility banner/toggle shown; profile is read-only for caregiver | G7: Medium | H7: PENDING
A8: EMERGENCY NOTIFICATIONS
A9: CG-05 | B9: FR4.6 | C9: Notifications | D9: Caregiver receives push notification when linked patient triggers SOS | E9: 1. Link Caregiver to patient 2. Trigger SOS from patient account 3. Check Caregiver device | F9: Push notification arrives within 5 seconds; notification shows patient name and emergency type | G9: Critical | H9: PENDING
A10: CG-06 | B10: FR3.3 | C10: Notifications | D10: Caregiver receives vibration alert if Vibration Feedback is enabled | E10: 1. Enable Vibration Feedback in Accessibility Settings 2. Trigger SOS from linked patient | F10: Device vibrates on SOS alert in addition to push notification | G10: High | H10: PENDING
A11: ADDED IN v2.0 — SRS GAPS & NEW FEATURES
A12: CG-07 | B12: FR7.2 | C12: Linking | D12: Patient and caregiver link through an email invitation (many-to-many) | E12: 1. Caregiver invites patient A and patient B 2. Both accept 3. Patient A also links a second caregiver | F12: Caregiver sees both patients; patient A sees both caregivers | G12: High | H12: PENDING
A13: CG-08 | B13: FR6.3, FR6.2 | C13: Live Map | D13: Caregiver sees the live map when a linked patient's SOS is accepted | E13: 1. Linked patient sends SOS 2. Responder accepts and moves 3. Caregiver taps "Track live" | F13: Map shows patient pin, moving ambulance marker, ETA and status timeline | G13: Critical | H13: PENDING
